Workbook

Sheet FrontP
A9: 03 | B9: 44316 | C9: Issued for Review | E9: ALL | F9: OKS/RSS | G9: OKS
A10: 02 | B10: 44279 | C10: Issued for Review | E10: ALL | F10: OKS/RSS | G10: OKS
A11: 01 | B11: 44235 | C11: Issued for Review | E11: ALL | F11: OKS/RSS | G11: OKS
A12: Rev | B12: Issued date | C12: Description | E12: Made by | F12: Chk'd by | G12: Disc. appr. | H12: Proj. appr. | I12: Client appr.
E13: Aibel AS
G14: Client Ref:
G15: 4503943297
A16: Project no: | D16: Project Title:
A17: 007990 | D17: Askja UPP and Krafla Field Engineering C-study
A18: Doc.Type: | D18: Area: | E18: System:
A19: LA | D19: 00 | E19: 00
A21: Document Title:
A22: Master Equipment List (MEL) - Askja Unmanned Process Platform (UPP)
A23: Document no.: | F23: Rev. | H23: Page:
A24: C232-AI-R-LA-00001 | F24: 02 | H24: 1 of 7

Sheet Info
F64: TR1244 Appendix 3 - Master Equipment List (MEL)
B66: Document owner information | G66: Project information
B67: Document ref.: | C67: TR1244 | G67: Project:
B68: Document rev. date: | C68: 44167 | G68: Equinor discipline responsible:
B69: Document approved by: | C69: TPD PRD EP EST | G69: Date:
G70: Rev:
G72: Signature:

Sheet Definitions
B3: MEL Column | C3: Description | D3: Relevant for class
B4: Tag Status | C4: Used for tracking changes from previous MEL version. NEW - Newly added or retagged items. Whole line shall be highlighted DIFF - Item will have a changed entry in at least one of its fields. Affected cells shall be highlighted. Comments shall be used to input the former cell content. EQUAL- No change from last version. | D4: B | E4: C | F4: D
B5: Building block | C5: To be entered if modification scope is divided into different blocks/packages. Project specific codes. | E5: C | F5: D
B6: Discipline | C6: Discipline code, ref. project specific TR0052 ENS (Engineering Numbering System). This is the 'OWNER' discipline of the equipment, as it would be procured . Example: R - Mechanical / E - Electrical / J - Automation / S - Safety | D6: B | E6: C | F6: D
B7: Cost Code COR | C7: Codes for Equipment and Bulk, ref. Standard Cost Coding System – (SCCS), as described in ISO 19008. Four letter codes to be entered for equipment, 3 letter codes for Bulk. Valid codes are given in TR1244 Appendix 4. Code of Resources (COR). | D7: B | E7: C | F7: D
B8: Tag Number | C8: Tag number for the reported item, which identifies a piece of equipment. Tag number to be in accordance with project specific ENS (Engineering Numbering System) ref. TR0052. | D8: B | E8: C | F8: D
B9: Top Tag | C9: Denotes if the tag number is the skid reference. If 'NO' then that item will be mounted on the associated skid reference. If 'YES' then this entry shall summarize the entire skid footprint and weight. | D9: B | E9: C | F9: D
B10: Skid Ref. | C10: Skid reference/ mounted on (if equipment weight is included in parent skid weights). This will define where the overall dimensions and weight are captured. | D10: B | E10: C | F10: D
B11: PO Package Number | C11: Project specific procurement order (PO) number. Only to be filled in when info is available | F11: D
B12: System Number | C12: System number for reported item. System number to be in accordance with project specific ENS (Engineering Numbering System), ref. TR0052. | D12: B | E12: C | F12: D
B13: Equinor Equipment Category (1 - 4) | C13: Equinor equipment categories in accordance with Equinor Standard Equipment List: 1. Industry standard, produced for offshore industry 2. Industry standard with Equinor Specific additional tech. requirements 3. Customized equipment to Equinor technical requirements 4. Multidiscipline package according to Equinor Equipment package list | D13: B | E13: C | F13: D
B14: Equipment Type Description | C14: Description of equipment component and service, item specific. | D14: B | E14: C | F14: D
B15: Area | C15: Area location codes on the platform for reported item, ref. project specific TR0052 ENS (Engineering Numbering System). Platform specific codes. | E15: C | F15: D
B16: Sub Area | C16: Sub area location on the platform for the reported item, to be entered when relevant. Platform specific codes. | E16: C | F16: D
B17: Function Area | C17: For new build projects, areas like separation area, compression area, etc are valid. Used for selecting bulk and structural density factors. For modification projects, this code is not applicable. | F17: D
B18: L / TT (mm) | C18: Lenght (L) of reported equipment / Tangent-to-tangent (TT) distance for horizontal vessels. The TT distance is referring to the straight, cylindrical length of a vessel, excluding the header. | D18: B | E18: C | F18: D
B19: W / ID (mm) | C19: Width (W) of reported equipment / Inner diameter (ID) for vessels. | D19: B | E19: C | F19: D
B20: H / TT (mm) | C20: Height (H) of reported equipment / Tangent-to-tangent (TT) distance for vertical vessels. The TT distance is referring to the straight, cylindrical hight of a vessel, excluding the header. | D20: B | E20: C | F20: D
B21: Footprint (m²) | C21: Equipment footprint area. Footprint = L x W for all equipment. | D21: B | E21: C | F21: D
B22: Modification Phase Code | C22: This code identifies at which stage (weight phase) in the project an item is installed, moved, changed or removed e.g. when a material handling activity takes place. To be used for projects where shutdown(s) is required. | E22: C | F22: D
B23: Modification Construction Code | C23: M - Bulk materials/items/assemblies installed in a module onshore before transport offshore. If there is more than one module, codes M1, M2 etc. should be entered. P - Prefabricated bulk materials/items/assemblies for offshore integration work (i.e. pipe spools, steelwork). I - Bulk materials/items purchased for offshore integration work (items which require NO prefab. work, installation work only, e.g. pumps, valves, cables, instruments etc.). Existing bulk materials/items which are to be moved or removed | D23: B | E23: C | F23: D
B24: Modification Handling Code | C24: New (greenfield) projects: PERM - Permanently installed equipment. TEMP - Temporarily installed equipment. FUT - Equipment installed in the future. Modification (brownfield) projects: NP - New permanently installed material/equipment. CP - Change of Permanently Installed / Revamp For equipment and tagged bulk. A change in design / weight of existing permanently installed item / equipment, i.e. revamp of internals in heat exchanger. Weight of new item installed is to be reported as CP. Weight of the existing part removed is to be reported as RP. MP - Moved Permanently. Material/equipment moved permanently to a new location (or back to its original location) and (re)installed (no changes to the moved object). MP does also include the dismantling ahead of the relocation and temporary moves (if relevant). NT - New temporarily installed material/equipment. Installation of temporary material/equipment. If weights are reported as NT, corresponding weights must be reported under RT. (When weights are reported as NT, corresponding weights are automatically reported as demolition in the summary sheets in TR1244). RT - Removal of Temporary items. Removal of temporarily installed equipment or bulk. Report weight of material/equipment to be dismantled. Ref NT. (When weights are reported as NT, corresponding weights are automatically reported as demolition in the summary sheets in TR1244). RP - Removal of Permanent items. Removal of permanently installed equipment or bulk material. Report weight of material/equipment to be dismantled. | D24: B | E24: C | F24: D
B25: Allowance (%) | C25: A weight allowance shall be added to the net reported weights to account for incompleteness in the definition of equipment, components and materials, ref. TR1244, section for Weight allowance. Weight allowance applied to Net Dry Weight only. | D25: B | E25: C | F25: D
B26: Net Dry Weight (kg) | C26: Equipment dry weight (excluding any allowances) obtained either by estimates from early design documents or present sketches, calculated WTO from drawings or 3D model, or as given in vendor data-sheets, ref. ISO 19901-5. | D26: B | E26: C | F26: D
B27: Gross Dry Weight (kg) | C27: Equipment gross weight, equal to reported weight: Net Dry Weight x (1 + (Weight Allowance/100)), ref. ISO 19901-5. | D27: B | E27: C | F27: D
B28: Content Weight (kg) | C28: Weight of content (fluids) in equipment/bulk during normal operating conditions, ref. ISO 19901-5. | D28: B | E28: C | F28: D
B29: Dry CoG East (mm) | C29: Global Center of Gravity (CoG) for the reported (dry) item in East direction. | E29: C | F29: D
B30: Dry CoG North (mm) | C30: Global Center of Gravity (CoG) for the reported (dry) item in North direction. | E30: C | F30: D
B31: Dry CoG Elevation (mm) | C31: Global Center of Gravity (CoG) for the reported (dry) item in Elevation direction. | E31: C | F31: D
B32: Price Source | C32: Source of the cost entered. Example: In house information/factorized, supplier budget price, etc. Hidden in native document | E32: (C) | F32: (D)
B33: Cost [Proj. currency] | C33: Procurement cost of the equipment in project currency. Procurement cost for offshore projects should be related to toptags alternatively PO numbers and extent is to be defined by project | E33: (C) | F33: (D)
B34: Cost Date | C34: Date for when the price information is obtained. | E34: (C) | F34: (D)
B35: Exch. rate | C35: Exchange rate from project currency to NOK (Norwegian Kroner). | E35: (C) | F35: (D)
B36: NOK | C36: Cost of reported item in NOK (Norwegian Kroner). | E36: (C) | F36: (D)
B37: Pressure 1 (Barg) | C37: Preliminary design pressure for the reported equipment. Generally, Pressure 1 denotes the minimum design pressure and Pressure 2 denotes the maximum design pressure. For mutli-fluid vessels (e.g. heat exchangers), Pressure 1 denotes the inlet pressure of the process medium and Pressure 2 denotes the outlet pressure of the process medium. | D37: Depending on equipment type
B38: Pressure 2 (Barg)
B39: Temp 1 (°C) | C39: Temperature information for reported equipment in degrees Celsius. Temp 2 to be used if more than one temperature needs to be specified. For mutli-fluid vessels (e.g. heat exchangers), Temp 1 denotes the inlet temperature of the process medium and Temp 2 denotes the outlet temperature of the process medium. Temperatures for coolant may be given in Remarks column | D39: Depending on equipment type
B40: Temp 2 (°C)
B41: Flow rate 1 (m³/hr) | C41: Design volumetric flow rate. Generally, Flow rate 1 denotes the minimum flow rate and Flow rate 2 denotes the maximum flow rate. For mutli-fluid vessels (e.g. heat exchangers), Flow rate 1 denotes the flow rate of the process medium and Flowrate 2 denotes the flow rate of the cooling medium. | D41: Depending on equipment type
B42: Flow rate 2 (m³/hr)
...

Sheet MEL
A2: MASTER EQUIPMENT LIST Multi discipline input | L2: Rev: | M2: 03 | U2: Total Net Dry Weight | V2: =SUBTOTAL(109,W7:W352) -> 1442398.7 | W2: kg
J3: Do not delete or change row | U3: Total Net Gross Weight | V3: =SUBTOTAL(109,X6:X351) -> 1657230 | W3: kg | X3: Resulting allow: | Y3: =(V3-V2)/V2 -> 0.14894031
A4: Project: | C4: Askja UPP C study | H4: Platform: | I4: Askja UPP | J4: 1-7 or modify columns A to BC. | L4: Date: | M4: 44316 | U4: Total Content Weight | V4: =SUBTOTAL(109,Y7:Y352) -> 278133.61 | W4: kg | AC4: Cost data per toptag/PO only, project to decide extent
A5: BCD | B5: CD | C5: BCD | D5: BCD | E5: BCD | F5: BCD | G5: BCD | H5: (D) | I5: BCD | J5: BCD | K5: BCD | L5: CD | M5: CD | N5: D | O5: BCD | P5: BCD | Q5: BCD | R5: BCD | S5: CD | T5: BCD | U5: BCD | V5: BCD | W5: BCD | X5: BCD | Y5: BCD | Z5: CD | AA5: CD | AB5: CD | AC5: (CD) | AD5: (CD) | AE5: (CD) | AF5: (CD) | AG5: (CD) | AW5: BCD | AX5: BCD | AY5: BCD | AZ5: BCD | BB5: BCD | BC5: BCD
A6: Tag Status | B6: Building block | C6: Discipline | D6: Cost Code COR | E6: Tag Number | F6: Top Tag | G6: Skid Ref. | H6: PO Package Number | I6: System Number | J6: Equinor Equipment Category (1 - 4) | K6: Equipment Type Description | L6: Area | M6: Sub Area | N6: Function Area | O6: L / TT (mm) | P6: W / ID (mm) | Q6: H / TT (mm) | R6: Footprint (m²) | S6: Modification Phase Code | T6: Modification Construction Code | U6: Modification Handling Code | V6: Allowance (%) | W6: Net Dry Weight (kg) | X6: Gross Dry Weight (kg) | Y6: Content Weight (kg) | Z6: Dry CoG East (mm) | AA6: Dry CoG North (mm) | AB6: Dry CoG Elevation (mm) | AC6: Price Source | AD6: Cost [Proj. currency] | AE6: Cost Date | AF6: Exch. rate | AG6: NOK | AH6: Pressure 1 (Barg) | AI6: Pressure 2 (Barg) | AJ6: Temp 1 (°C) | AK6: Temp 2 (°C) | AL6: Flow rate 1 (m³/hr) | AM6: Flow rate 2 (m³/hr) | AN6: Capacity (m³) | AO6: Heat transfer medium (type) | AP6: Speed (RPM) | AQ6: Heat Exchanged per Unit (kW) | AR6: Shaft Power (kW) | AS6: Rated Power (kW) | AT6: Heat Transfer Surface Area [m²] | AU6: Material 1 | AV6: Material 2 | AW6: Reference /Source | AX6: Reference doc., dwg., P&ID etc. | AY6: Risk: Weight accuracy | AZ6: Risk: Footprint accuracy | BA6: Risk: Design basis | BB6: Risk comments | BC6: Remarks | BD6: CLASS_OF_ACTIVITY | BE6: CLASS_OF_FUNCTIONAL_OBJECT | BF6: CLASS_OF_INANIMATE_PHYSICAL_OBJECT
A7: =0 -> 0 | B7: =0 -> 0 | C7: =0 -> 0 | D7: =0 -> 0 | E7: =0 -> 0 | G7: =0 -> 0 | I7: =0 -> 0 | K7: =0 -> 0 | L7: =0 -> 0 | M7: =0 -> 0 | N7: =0 -> 0 | O7: =0 -> 0 | P7: =0 -> 0 | Q7: =0 -> 0 | R7: =0 -> 0 | ... W7: =0 -> 0 | X7: =W7*(1+V7) -> 0 | Y7: =0 -> 0 | Z7: =0 -> 0 | AA7: =0 -> 0 | AB7: =0 -> 0 | AC7: =0 -> 0 | AD7: =0 -> 0 | AE7: =0 -> 0 | AF7: =0 -> 0 | ... AN7: =0 -> 0 | AT7: =0 -> 0 | AU7: =0 -> 0 | AV7: =0 -> 0 | AW7: =0 -> 0 | AX7: =0 -> 0 | BC7: =0 -> 0
A8: DIFF | C8: E | E8: A-18BY001 | H8: - | I8: 18 | K8: Optical Junction Box Central | L8: Cellar deck | M8: AP200 | N8: AP200 | O8: 1000 | P8: 800 | Q8: 400 | R8: =(O8*P8)/1000000 -> 0.8 | U8: PERM | V8: 0.15 | W8: 300 | X8: =W8*(1+V8) -> 345 | BC8: Interface Patch boxes for subsea cables
A9: DIFF | C9: E | E9: A-18BY002 | H9: - | I9: 18 | K9: Optical Junction Box for UID | L9: Cellar deck | M9: AP200 | N9: AP200 | O9: 1000 | P9: 800 | Q9: 400 | R9: =(O9*P9)/1000000 -> 0.8 | U9: PERM | V9: 0.15 | W9: 300 | X9: =W9*(1+V9) -> 345 | BC9: Interface Patch boxes for subsea cables. To be used for UID
C10: J | D10: ERCT | E10: A-18CT001 | H10: EI001 | I10: 18 | K10: Hydraulic Power Unit (LP and HP) | L10: Cellar deck | M10: AP200 | N10: AP200 | O10: 5300 | P10: 2400 | Q10: 3000 | R10: =(O10*P10)/1000000 -> 12.72 | U10: PERM | V10: 0.15 | W10: 10000 | X10: =W10*(1+V10) -> 11500 | Y10: 4000 | Z10: 320199 | AA10: 396399 | AB10: 514025 | BC10: Based on Cre8 GA ,Size and number of connections to be updated due to new field configurairion
C11: J | D11: EJJF | E11: A-18JC001 | H11: CPI | I11: 18 | K11: DAS/DTS system cabinet | L11: Cellar deck | M11: AQ200 | N11: AQ200 | O11: 1000 | P11: 800 | Q11: 2000 | R11: =(O11*P11)/1000000 -> 0.8 | U11: PERM | V11: 0.15 | W11: 300 | X11: =W11*(1+V11) -> 345 | Z11: 326290 | AA11: 383938 | AB11: 502360
C12: J | E12: A-18JF001 | H12: CPI | I12: 18 | K12: DAS/DTS Fibre splice cabinet | L12: Cellar deck | M12: AP200 | N12: AP200 | O12: 1000 | P12: 800 | Q12: 2000 | R12: =(O12*P12)/1000000 -> 0.8 | U12: PERM | V12: 0.15 | W12: 300 | X12: =W12*(1+V12) -> 345
A13: NEW | C13: J | D13: EJJF | E13: A-18JF002 | H13: CPI | I13: 18 | K13: Down hole monitoring cabinet | L13: Cellar deck | M13: AQ200 | N13: AQ200 | O13: 1000 | P13: 800 | Q13: 2000 | R13: =(O13*P13)/1000000 -> 0.8 | U13: PERM | V13: 0.15 | W13: 300 | X13: =W13*(1+V13) -> 345 | Z13: 326290 | AA13: 383938 | AB13: 502360
C14: R | E14: A-18LE001 | H14: - | I14: 18 | K14: Temporary Pig Receiver - Krafla LP/Central (14") | L14: Mezzanine deck | M14: AP300 | N14: AP300 CANTILEVER | O14: 6200 | P14: 400 | Q14: 400 | R14: =(O14*P14)/1000000 -> 2.48 | U14: TEMP | V14: 0.15 | W14: 6770 | X14: =W14*(1+V14) -> 7785.5 | Z14: 297399 | AA14: 369000 | AB14: 508090
C15: R | E15: A-18LE002 | H15: - | I15: 18 | K15: Temporary Pig Receiver - Krafla HP (8") | L15: Mezzanine deck | M15: AP300 | N15: AP300 CANTILEVER | O15: 5600 | P15: 400 | Q15: 400 | R15: =(O15*P15)/1000000 -> 2.24 | U15: TEMP | V15: 0.15 | W15: 6770 | X15: =W15*(1+V15) -> 7785.5 | Z15: 297399 | AA15: 369000 | AB15: 508090
C16: J | E16: A-18UX001 | H16: EI014 | I16: 18 | K16: TUTU/HTP Service Umbilical from PDQ | L16: Cellar deck | M16: AP200 | N16: AP200 | O16: 3400 | P16: 1200 | Q16: 2400 | R16: =(O16*P16)/1000000 -> 4.08 | U16: PERM | V16: 0.15 | W16: 1200 | X16: =W16*(1+V16) -> 1380 | Z16: 317143 | AA16: 378400 | AB16: 500000 | BC16: Contains only interface to subsea umbilicals for liquid only
C17: J | E17: A-18UX002 | H17: EI014 | I17: 18 | K17: TUTU/HTP Service Umbilical to Central and Krafla | L17: Cellar deck | M17: AP200 | N17: AP200 | O17: 1600 | P17: 800 | Q17: 2000 | R17: =(O17*P17)/1000000 -> 1.28 | U17: PERM | V17: 0.15 | W17: 700 | X17: =W17*(1+V17) -> 805 | Z17: 314618 | AA17: 379775 | AB17: 500000 | BC17: Contains only interface to subsea umbilicals for liquid only
C18: E | D18: EEEC | E18: A-19EC001 | H18: - | I18: 19 | K18: DEH Control Cabinet Central and Krafla LP Pipeline | L18: Mezzanine deck | M18: AQ300 | N18: HV equipment room | O18: 600 | P18: 600 | Q18: 2000 | R18: =(O18*P18)/1000000 -> 0.36 | U18: PERM | V18: 0.15 | W18: 500 | X18: 575 | Z18: 323503 | AA18: 379800 | AB18: 509200 | BC18: for the HP pipeline , to be decided on c study phase
A19: NEW | C19: E | D19: EEEC | E19: A-19EC002 | H19: - | I19: 19 | K19: DCFO Remote Control Cabinet | L19: Mezzanine deck | M19: AQ300 | N19: HV equipment room | O19: 1000 | P19: 800 | Q19: 2200 | R19: =(O19*P19)/1000000 -> 0.8 | U19: PERM | V19: 0.15 | W19: 300 | X19: 575 | Z19: 326529 | AA19: 379970 | AB19: 509400 | BC19: for the HP pipeline , to be decided on c study phase
A20: NEW | C20: E | D20: EEEC | E20: A-19EC003 | H20: - | I20: 19 | K20: UID Power Control Cabinet | L20: Cellar deck | M20: AQ200 | N20: CER 2 | O20: 1000 | P20: 800 | Q20: 2200 | R20: =(O20*P20)/1000000 -> 0.8 | U20: PERM | V20: 0.15 | W20: 400 | X20: 575 | Z20: 327292 | AA20: 383938 | AB20: 502360 | BC20: for the HP pipeline , to be decided on c study phase
A21: NEW | C21: E | D21: EEER | E21: A-19ER001 | H21: - | I21: 19 | K21: DCFO Power Unit A | L21: Mezzanine deck | M21: AQ300 | N21: HV equipment room | O21: 1000 | P21: 800 | Q21: 2200 | R21: =O21*P21/1000000 -> 0.8 | U21: PERM | V21: 0.15 | W21: 450 | X21: =W21*(1+V21) -> 517.5 | Z21: 323523 | AA21: 379970 | AB21: 509400
A22: DIFF | C22: E | D22: EEER | E22: A-19ER002 | H22: - | I22: 19 | K22: DCFO Power Unit B | L22: Mezzanine deck | M22: AQ300 | N22: HV equipment room | O22: 1000 | P22: 800 | Q22: 2200 | R22: =O22*P22/1000000 -> 0.8 | U22: PERM | V22: 0.15 | W22: 450 | X22: =W22*(1+V22) -> 517.5 | Z22: 324525 | AA22: 379970 | AB22: 509200 | AS22: 500
C23: E | D23: EEET | E23: A-19ET001 | H23: - | I23: 19 | K23: DEH Transformer Central and Krafla LP Pipeline | L23: Mezzanine deck | M23: AQ300 | N23: MV Transformer room | O23: 3000 | P23: 1700 | Q23: 3000 | R23: =(O23*P23)/1000000 -> 5.1 | U23: PERM | V23: 0.15 | W23: 8500 | X23: 9000 | Z23: 341447 | AA23: 399732 | AB23: 508535 | AS23: 5000 | BC23: for the HP pipeline , to be decided on c study phase
A24: NEW | C24: E | D24: EEEX | E24: A-19EX001 | H24: - | I24: 19 | K24: Cable Routing Cabinet | L24: Mezzanine deck | M24: AQ300 | N24: HV equipment room | O24: 1000 | P24: 800 | Q24: 2200 | R24: =(O24*P24)/1000000 -> 0.8 | U24: PERM | V24: 0.15 | W24: 300 | X24: 575 | Z24: 326529 | AA24: 379970 | AB24: 509400 | BC24: for the HP pipeline , to be decided on c study phase
C25: E | D25: EEEY | E25: A-19EY001 | H25: - | I25: 19 | K25: DEH Inductor L1 Unit Central and Krafla LP Pipeline | L25: Mezzanine deck | M25: AQ300 | N25: HV equipment room | O25: 3600 | P25: 1300 | Q25: 2700 | R25: =(O25*P25)/1000000 -> 4.68 | U25: PERM | V25: 0.15 | W25: 7200 | X25: 8280 | Z25: 335352 | AA25: 372265 | AB25: 508350 | BC25: for the HP pipeline , to be decided on c study phase
C26: E | D26: EEEY | E26: A-19EY002 | H26: - | I26: 19 | K26: DEH Capacitance C1 Unit Central and Krafla LP Pipeline | L26: Mezzanine deck | M26: AQ300 | N26: HV equipment room | O26: 3600 | P26: 1300 | Q26: 2400 | R26: =(O26*P26)/1000000 -> 4.68 | U26: PERM | V26: 0.15 | W26: 2200 | X26: 2530 | Z26: 327353 | AA26: 372262 | AB26: 508200 | BC26: for the HP pipeline , to be decided on c study phase
C27: E | D27: EEEY | E27: A-19EY003 | H27: - | I27: 19 | K27: DEH Capacitance C2 Unit Central and Krafla LP Pipeline | L27: Mezzanine deck | M27: AQ300 | N27: HV equipment room | O27: 3600 | P27: 1300 | Q27: 2400 | R27: =(O27*P27)/1000000 -> 4.68 | U27: PERM | V27: 0.15 | W27: 3800 | X27: =W27*(1+V27) -> 4370 | Z27: 340352 | AA27: 372265 | AB27: 508200 | BC27: for the HP pipeline , to be decided on c study phase
A28: NEW | C28: J | D28: EJJB | E28: A-19JQ001 | H28: CPI | I28: 19 | K28: Subsea contractor network cabinet SDPU | L28: Cellar deck | M28: AQ200 | N28: CER 2 | O28: 1000 | P28: 800 | Q28: 2200 | R28: =(O28*P28)/1000000 -> 0.8 | U28: PERM | V28: 0.15 | W28: 200 | X28: =W28*(1+V28) -> 230 | Z28: 332000 | AA28: 374740 | AB28: 502360
A29: NEW | C29: J | D29: EJJB | E29: A-19JQ002 | H29: CPI | I29: 19 | K29: Subsea contractor network cabinet SGRU A | L29: Cellar deck | M29: AQ200 | N29: CER 2 | O29: 800 | P29: 800 | Q29: 2200 | R29: =(O29*P29)/1000000 -> 0.64 | U29: PERM | V29: 0.15 | W29: 200 | X29: =W29*(1+V29) -> 230 | Z29: 332802 | AA29: 374740 | AB29: 502360
A30: NEW | C30: J | D30: EJJB | E30: A-19JQ003 | H30: CPI | I30: 19 | K30: Subsea contractor network cabinet SGRU B | L30: Cellar deck | M30: AQ200 | N30: CER 2 | O30: 800 | P30: 800 | Q30: 2200 | R30: =(O30*P30)/1000000 -> 0.64 | U30: PERM | V30: 0.15 | W30: 200 | X30: =W30*(1+V30) -> 230 | Z30: 333604 | AA30: 374740 | AB30: 502360
A31: NEW | C31: J | D31: EJJB | E31: A-19JQ004 | H31: CPI | I31: 19 | K31: Subsea contractor server cabinet SGSU | L31: Cellar deck | M31: AQ200 | N31: CER 2 | O31: 800 | P31: 800 | Q31: 2200 | R31: =(O31*P31)/1000000 -> 0.64 | U31: PERM | V31: 0.15 | W31: 200 | X31: =W31*(1+V31) -> 230 | Z31: 336010 | AA31: 374740 | AB31: 502360
A32: DIFF | C32: E | D32: EEER | E32: A-20ER001A | H32: ER007 | I32: 20 | K32: VSD Liquid Export Pump A | L32: Mezzanine deck | M32: AQ400 | N32: HV VSD room | O32: 3300 | P32: 1150 | Q32: 2400 | R32: =(O32*P32)/1000000 -> 3.795 | U32: PERM | V32: 0.15 | W32: 4500 | X32: =W32*(1+V32) -> 5175 | Z32: 333271 | AA32: 398994 | AB32: 516415 | AU32: 22Cr Duplex
A33: DIFF | C33: E | D33: EEER | E33: A-20ER001B | H33: ER007 | I33: 20 | K33: VSD Liquid Export Pump B | L33: Mezzanine deck | M33: AQ400 | N33: HV VSD room | O33: 3300 | P33: 1150 | Q33: 2400 | R33: =(O33*P33)/1000000 -> 3.795 | U33: PERM | V33: 0.15 | W33: 4500 | X33: =W33*(1+V33) -> 5175 | Z33: 333279 | AA33: 395644 | AB33: 516386 | AU33: 22Cr Duplex
C34: R | E34: A-20LE001 | H34: - | I34: 20 | K34: Temporary Pig Launcher - Liquid Export (for RFO and R113 inspection) | L34: Mezzanine deck | M34: AP300 | N34: AP300 CANTILEVER | O34: 6200 | P34: 400 | Q34: 400 | R34: =(O34*P34)/1000000 -> 2.48 | U34: TEMP | V34: 0.15 | W34: 6770 | X34: =W34*(1+V34) -> 7785.5 | Z34: 297399 | AA34: 369000 | AB34: 508090
C35: R | D35: ERPA | E35: A-20PA001A | F35: NO | G35: A-20PZ001A | H35: ER007 | I35: 20 | K35: Liquid Export Pump A | L35: Cellar deck | M35: AP200 | N35: SKID | O35: 0 | P35: 0 | Q35: 0 | R35: 0 | U35: PERM | Z35: 304000 | AA35: 399000 | AB35: 501370 | AL35: 595 | AU35: 22Cr Duplex
C36: E | D36: ERPA | E36: A-20PA001A-M01 | F36: NO | G36: A-20PZ001A | H36: ER007 | I36: 20 | K36: Liquid Export Pump A Motor | L36: Cellar deck | M36: AP200 | N36: SKID | O36: 0 | P36: 0 | Q36: 0 | R36: 0 | U36: PERM | Z36: 0 | AA36: 0 | AB36: 0 | AS36: 1065
C37: R | D37: ERPA | E37: A-20PA001B | F37: NO | G37: A-20PZ001B | H37: ER007 | I37: 20 | K37: Liquid Export Pump B | L37: Cellar deck | M37: AP200 | N37: SKID | O37: 0 | P37: 0 | Q37: 0 | R37: 0 | U37: PERM | Z37: 304000 | AA37: 393000 | AB37: 501370 | AL37: 595 | AU37: 22Cr Duplex
C38: E | D38: ERPA | E38: A-20PA001B-M01 | F38: NO | G38: A-20PZ001B | H38: ER007 | I38: 20 | K38: Liquid Export Pump B Motor | L38: Cellar deck | M38: AP200 | N38: SKID | O38: 0 | P38: 0 | Q38: 0 | R38: 0 | U38: PERM | Z38: 0 | AA38: 0 | AB38: 0 | AS38: 1065
A39: DIFF | C39: R | D39: ERPZ | E39: A-20PZ001A | F39: YES | H39: ER007 | I39: 20 | K39: Liquid Export Pump A Skid | L39: Cellar deck | M39: AP200 | N39: AP200 | O39: 8500 | P39: 2400 | Q39: 2400 | R39: =(O39*P39)/1000000 -> 20.4 | U39: PERM | V39: 0.15 | W39: 26500 | X39: =W39*(1+V39) -> 30475 | Z39: 304000 | AA39: 399000 | AB39: 501370 | AU39: 25Cr Duplex | BB39: Gas carry under percentage to be finalized in process design Noise enclosure details to be finlized | BC39: Sulzer including lube oil system. including estimate for noise enclosure(5000kg) | BD39: http://data.posccaesar.org/rdl/RDS9657917 | BE39: http://data.posccaesar.org/rdl/RDS278594 | BF39: http://data.posccaesar.org/rdl/RDS14196773
A40: DIFF | C40: R | D40: ERPZ | E40: A-20PZ001B | F40: YES | H40: ER007 | I40: 20 | K40: Liquid Export Pump B Skid | L40: Cellar deck | M40: AP200 | N40: AP200 | O40: 8500 | P40: 2400 | Q40: 2400 | R40: =(O40*P40)/1000000 -> 20.4 | U40: PERM | V40: 0.15 | W40: 26500 | X40: =W40*(1+V40) -> 30475 | Z40: 304000 | AA40: 393000 | AB40: 501370 | AU40: 25Cr Duplex | BB40: Gas carry under percentage to be finalized in process design Noise enclosure details to be finlized | BC40: Sulzer including lube oil system. including estimate for noise enclosure(5000kg) | BD40: http://data.posccaesar.org/rdl/RDS9657917 | BE40: http://data.posccaesar.org/rdl/RDS278594 | BF40: http://data.posccaesar.org/rdl/RDS14196773
A41: DIFF | C41: R | D41: ERVA | E41: A-20VA001 | H41: ER002 | I41: 20 | K41: Inlet Separator | L41: Mezzanine deck | M41: AP300 | N41: AP300,AP400 | O41: 0 | P41: 3500 | Q41: 6600 | R41: =(P41*P41)/1000000 -> 12.25 | U41: PERM | V41: 0.15 | W41: 106600 | X41: =W41*(1+V41) -> 122590 | Y41: 80000 | Z41: 301200 | AA41: 387000 | AB41: 510447.5 | AH41: FV | AI41: 100 | AJ41: -46 | AK41: 125 | AN41: 80 | AU41: P500QL2 + Alloy 625 w.o. | AV41: internals 22Cr Duplex | BB41: Slug volume uncertainty (flow assurance) Gas carry under uncertainty | BC41: SLB proposal (rev 3) , vertical 2 phase separator with hemispherical heads . (weight of internals:9000kg) | BD41: http://data.posccaesar.org/rdl/RDS9647297 | BE41: http://data.posccaesar.org/rdl/RDS2194378711 | BF41: http://data.posccaesar.org/rdl/RDS291959
...

Sheet Reference Info
B2: Aibel
B3: EQUIPMENT LIST | N3: Page No.: 2 of 10
N4: Date: 24.03.2021
B5: Document No.: C232-AI-R-LA-00001 | N5: Rev. No.: 02
C7: Preliminary only
B8: Preliminary Package List | D8: Resp | G8: Main Area Codes | H8: Main Area Description | K8: Module
B9: Pck no. | C9: Package Description | D9: Aibel | E9: Company
B10: ER001 | C10: Gas Compressor Package | E10: X | G10: AF000 | H10: Flare tower
B11: ER002 | C11: Inlet Separator Package | D11: X | G11: AK000 | H11: Crane
B12: ER003 | C12: Gas Scrubbers | D12: X | G12: AJ000 | H12: Jacket
B13: ER004 | C13: Shell & Tube Exchangers | D13: X | G13: AP110 | H13: Stair tower - west | K13: Process Module
B14: ER005 | C14: Open | D14: X | G14: AQ110 | H14: Stair tower - east | K14: Utility Module
B15: ER006 | C15: G2P Mixer Package | D15: X | G15: AP100 | H15: W2W deck | K15: Process Module
B16: ER007 | C16: Liquid Export Pumps | D16: X | G16: AP200 | H16: Cellar deck | K16: Process Module
B17: ER008 | C17: Positive Displacement Pumps (HOLD) | D17: X | G17: AP300 | H17: Mezzanine deck | K17: Process Module
B18: ER009 | C18: Plate and Frame Exchangers | D18: X | G18: AP400 | H18: Process deck | K18: Process Module
B19: ER010 | C19: TEG Regeneration | D19: X | G19: AP500 | H19: Weather deck | K19: Process Module
B20: ER011 | C20: Seawater Lift Pumps | D20: X | G20: AQ200 | H20: Cellar deck | K20: Utility Module
B21: ER012 | C21: Seawater Filtration Pck | D21: X | G21: AQ300 | H21: Mezzanine deck | K21: Utility Module
B22: ER013 | C22: Misc Pressure Vessels | D22: X | G22: AQ400 | H22: Process deck | K22: Utility Module
B23: ER014 | C23: Misc Atmospheric Tanks | D23: X
B24: ER015 | C24: Electro Chlorination Package | D24: X
B25: ER016 | C25: Pedestal Crane | D25: X | E25: X
B26: ER017 | C26: Misc. Lifting / Material Handling Equipment | D26: X
B27: ER018 | C27: Misc Centrifugal Pumps | D27: X
B28: ER019 | C28: Relif Vent Tip Pck incl. Ignition Pck | D28: X
B29: ER020 | C29: Electric Heaters | D29: X
B30: ES001 | C30: Escape Chute | D30: X
B31: EE001 | C31: HV Tranformers | D31: X
B32: EE002 | C32: HV/LV Switchgear | D32: X
B33: EE003 | C33: UPS Package | D33: X
B34: EE007 | C34: VSD Package - include in mechanical/HVAC packages? | D34: X
B35: EI101 | C35: SAS Package | D35: X | E35: X
B36: ET001 | C36: Telecom Equipment | D36: X
B37: EH001 | C37: HVAC Equipment | D37: X
B38: ES002 | C38: Misc Firefighting Equipment | D38: X
B39: EI106 | C39: Drones/Robotics
B40: EE006 | C40: Nav Aid | D40: X
B41: EE005 | C41: LV Distribution Boards | D41: X
B42: EE004 | C42: LV Transformers | D42: X
...

Sheet Summary
B2: Summary per area
B3: Area | C3: Description | D3: Footprint PERM (m2) | E3: Footprint FUT/ TEMP (m2) | F3: Footprint total (m2) | G3: Net Dry Weight PERM (kg) | H3: Net Dry Weight FUT/ TEMP (kg) | I3: Net Dry Weight total (kg) | J3: Gross Dry Weight PERM (kg) | K3: Gross Dry Weight FUT/ TEMP (kg) | L3: Gross Dry Weight total (kg) | M3: Content Weight PERM (kg) | N3: Content Weight FUT/ TEMP (kg) | O3: Content Weight total (kg)
B4: Cellar deck | D4: =SUMIFS(MEL!R:R,MEL!R:R,"<>",MEL!$L:$L,$B4,MEL!$U:$U,"PERM") -> 340.8906 | E4: =SUMIFS(MEL!R:R,MEL!R:R,"<>",MEL!$L:$L,$B4,MEL!$U:$U,"TEMP")+SUMIFS(MEL!R:R,MEL!R:R,"<>",MEL!$L:$L,$B4,MEL!$U:$U,"FUT") -> 29.247344 | F4: =D4+E4 -> 370.13794 | G4: =SUMIFS(MEL!W:W,MEL!W:W,"<>",MEL!$L:$L,$B4,MEL!$U:$U,"PERM") -> 291420 | H4: =SUMIFS(MEL!W:W,MEL!W:W,"<>",MEL!$L:$L,$B4,MEL!$U:$U,"TEMP")+SUMIFS(MEL!W:W,MEL!W:W,"<>",MEL!$L:$L,$B4,MEL!$U:$U,"FUT") -> 21200 | I4: =G4+H4 -> 312620 | J4: =SUMIFS(MEL!X:X,MEL!X:X,"<>",MEL!$L:$L,$B4,MEL!$U:$U,"PERM") -> 335242 | K4: =SUMIFS(MEL!X:X,MEL!X:X,"<>",MEL!$L:$L,$B4,MEL!$U:$U,"TEMP")+SUMIFS(MEL!X:X,MEL!X:X,"<>",MEL!$L:$L,$B4,MEL!$U:$U,"FUT") -> 24380 | L4: =J4+K4 -> 359622 | M4: =SUMIFS(MEL!Y:Y,MEL!Y:Y,"<>",MEL!$L:$L,$B4,MEL!$U:$U,"PERM") -> 90300 | N4: =SUMIFS(MEL!Y:Y,MEL!Y:Y,"<>",MEL!$L:$L,$B4,MEL!$U:$U,"TEMP")+SUMIFS(MEL!Y:Y,MEL!Y:Y,"<>",MEL!$L:$L,$B4,MEL!$U:$U,"FUT") -> 0 | O4: =M4+N4 -> 90300
B5: Mezzanine deck | D5: =SUMIFS(MEL!R:R,MEL!R:R,"<>",MEL!$L:$L,$B5,MEL!$U:$U,"PERM") -> 211.5748 | E5: =SUMIFS(MEL!R:R,MEL!R:R,"<>",MEL!$L:$L,$B5,MEL!$U:$U,"TEMP")+SUMIFS(MEL!R:R,MEL!R:R,"<>",MEL!$L:$L,$B5,MEL!$U:$U,"FUT") -> 45.7356 | F5: =D5+E5 -> 257.3104 | G5: =SUMIFS(MEL!W:W,MEL!W:W,"<>",MEL!$L:$L,$B5,MEL!$U:$U,"PERM") -> 413971.74 | H5: =SUMIFS(MEL!W:W,MEL!W:W,"<>",MEL!$L:$L,$B5,MEL!$U:$U,"TEMP")+SUMIFS(MEL!W:W,MEL!W:W,"<>",MEL!$L:$L,$B5,MEL!$U:$U,"FUT") -> 58800 | I5: =G5+H5 -> 472771.74 | J5: =SUMIFS(MEL!X:X,MEL!X:X,"<>",MEL!$L:$L,$B5,MEL!$U:$U,"PERM") -> 475177.5 | K5: =SUMIFS(MEL!X:X,MEL!X:X,"<>",MEL!$L:$L,$B5,MEL!$U:$U,"TEMP")+SUMIFS(MEL!X:X,MEL!X:X,"<>",MEL!$L:$L,$B5,MEL!$U:$U,"FUT") -> 67620 | L5: =J5+K5 -> 542797.5 | M5: =SUMIFS(MEL!Y:Y,MEL!Y:Y,"<>",MEL!$L:$L,$B5,MEL!$U:$U,"PERM") -> 84700 | N5: =SUMIFS(MEL!Y:Y,MEL!Y:Y,"<>",MEL!$L:$L,$B5,MEL!$U:$U,"TEMP")+SUMIFS(MEL!Y:Y,MEL!Y:Y,"<>",MEL!$L:$L,$B5,MEL!$U:$U,"FUT") -> 0 | O5: =M5+N5 -> 84700
B6: Process deck | D6: =SUMIFS(MEL!R:R,MEL!R:R,"<>",MEL!$L:$L,$B6,MEL!$U:$U,"PERM") -> 210.622 | E6: =SUMIFS(MEL!R:R,MEL!R:R,"<>",MEL!$L:$L,$B6,MEL!$U:$U,"TEMP")+SUMIFS(MEL!R:R,MEL!R:R,"<>",MEL!$L:$L,$B6,MEL!$U:$U,"FUT") -> 6.73 | F6: =D6+E6 -> 217.352 | G6: =SUMIFS(MEL!W:W,MEL!W:W,"<>",MEL!$L:$L,$B6,MEL!$U:$U,"PERM") -> 231324 | H6: =SUMIFS(MEL!W:W,MEL!W:W,"<>",MEL!$L:$L,$B6,MEL!$U:$U,"TEMP")+SUMIFS(MEL!W:W,MEL!W:W,"<>",MEL!$L:$L,$B6,MEL!$U:$U,"FUT") -> 5400 | I6: =G6+H6 -> 236724 | J6: =SUMIFS(MEL!X:X,MEL!X:X,"<>",MEL!$L:$L,$B6,MEL!$U:$U,"PERM") -> 265275.1 | K6: =SUMIFS(MEL!X:X,MEL!X:X,"<>",MEL!$L:$L,$B6,MEL!$U:$U,"TEMP")+SUMIFS(MEL!X:X,MEL!X:X,"<>",MEL!$L:$L,$B6,MEL!$U:$U,"FUT") -> 6210 | L6: =J6+K6 -> 271485.1 | M6: =SUMIFS(MEL!Y:Y,MEL!Y:Y,"<>",MEL!$L:$L,$B6,MEL!$U:$U,"PERM") -> 66933.61 | N6: =SUMIFS(MEL!Y:Y,MEL!Y:Y,"<>",MEL!$L:$L,$B6,MEL!$U:$U,"TEMP")+SUMIFS(MEL!Y:Y,MEL!Y:Y,"<>",MEL!$L:$L,$B6,MEL!$U:$U,"FUT") -> 0 | O6: =M6+N6 -> 66933.61
B7: Weather deck | D7: =SUMIFS(MEL!R:R,MEL!R:R,"<>",MEL!$L:$L,$B7,MEL!$U:$U,"PERM") -> 118.85965 | E7: =SUMIFS(MEL!R:R,MEL!R:R,"<>",MEL!$L:$L,$B7,MEL!$U:$U,"TEMP")+SUMIFS(MEL!R:R,MEL!R:R,"<>",MEL!$L:$L,$B7,MEL!$U:$U,"FUT") -> 47.567564 | F7: =D7+E7 -> 166.42721 | G7: =SUMIFS(MEL!W:W,MEL!W:W,"<>",MEL!$L:$L,$B7,MEL!$U:$U,"PERM") -> 201698 | H7: =SUMIFS(MEL!W:W,MEL!W:W,"<>",MEL!$L:$L,$B7,MEL!$U:$U,"TEMP")+SUMIFS(MEL!W:W,MEL!W:W,"<>",MEL!$L:$L,$B7,MEL!$U:$U,"FUT") -> 42020 | I7: =G7+H7 -> 243718 | J7: =SUMIFS(MEL!X:X,MEL!X:X,"<>",MEL!$L:$L,$B7,MEL!$U:$U,"PERM") -> 231952.7 | K7: =SUMIFS(MEL!X:X,MEL!X:X,"<>",MEL!$L:$L,$B7,MEL!$U:$U,"TEMP")+SUMIFS(MEL!X:X,MEL!X:X,"<>",MEL!$L:$L,$B7,MEL!$U:$U,"FUT") -> 48323 | L7: =J7+K7 -> 280275.7 | M7: =SUMIFS(MEL!Y:Y,MEL!Y:Y,"<>",MEL!$L:$L,$B7,MEL!$U:$U,"PERM") -> 28700 | N7: =SUMIFS(MEL!Y:Y,MEL!Y:Y,"<>",MEL!$L:$L,$B7,MEL!$U:$U,"TEMP")+SUMIFS(MEL!Y:Y,MEL!Y:Y,"<>",MEL!$L:$L,$B7,MEL!$U:$U,"FUT") -> 0 | O7: =M7+N7 -> 28700
B8: Stair tower east | D8: =SUMIFS(MEL!R:R,MEL!R:R,"<>",MEL!$L:$L,$B8,MEL!$U:$U,"PERM") -> 0 | E8: =SUMIFS(MEL!R:R,MEL!R:R,"<>",MEL!$L:$L,$B8,MEL!$U:$U,"TEMP")+SUMIFS(MEL!R:R,MEL!R:R,"<>",MEL!$L:$L,$B8,MEL!$U:$U,"FUT") -> 2.94 | F8: =D8+E8 -> 2.94 | G8: =SUMIFS(MEL!W:W,MEL!W:W,"<>",MEL!$L:$L,$B8,MEL!$U:$U,"PERM") -> 0 | H8: =SUMIFS(MEL!W:W,MEL!W:W,"<>",MEL!$L:$L,$B8,MEL!$U:$U,"TEMP")+SUMIFS(MEL!W:W,MEL!W:W,"<>",MEL!$L:$L,$B8,MEL!$U:$U,"FUT") -> 1200 | I8: =G8+H8 -> 1200 | J8: =SUMIFS(MEL!X:X,MEL!X:X,"<>",MEL!$L:$L,$B8,MEL!$U:$U,"PERM") -> 0 | K8: =SUMIFS(MEL!X:X,MEL!X:X,"<>",MEL!$L:$L,$B8,MEL!$U:$U,"TEMP")+SUMIFS(MEL!X:X,MEL!X:X,"<>",MEL!$L:$L,$B8,MEL!$U:$U,"FUT") -> 1380 | L8: =J8+K8 -> 1380 | M8: =SUMIFS(MEL!Y:Y,MEL!Y:Y,"<>",MEL!$L:$L,$B8,MEL!$U:$U,"PERM") -> 0 | N8: =SUMIFS(MEL!Y:Y,MEL!Y:Y,"<>",MEL!$L:$L,$B8,MEL!$U:$U,"TEMP")+SUMIFS(MEL!Y:Y,MEL!Y:Y,"<>",MEL!$L:$L,$B8,MEL!$U:$U,"FUT") -> 0 | O8: =M8+N8 -> 0
B9: W2W deck | D9: =SUMIFS(MEL!R:R,MEL!R:R,"<>",MEL!$L:$L,$B9,MEL!$U:$U,"PERM") -> 4 | E9: =SUMIFS(MEL!R:R,MEL!R:R,"<>",MEL!$L:$L,$B9,MEL!$U:$U,"TEMP")+SUMIFS(MEL!R:R,MEL!R:R,"<>",MEL!$L:$L,$B9,MEL!$U:$U,"FUT") -> 0 | F9: =D9+E9 -> 4 | G9: =SUMIFS(MEL!W:W,MEL!W:W,"<>",MEL!$L:$L,$B9,MEL!$U:$U,"PERM") -> 2800 | H9: =SUMIFS(MEL!W:W,MEL!W:W,"<>",MEL!$L:$L,$B9,MEL!$U:$U,"TEMP")+SUMIFS(MEL!W:W,MEL!W:W,"<>",MEL!$L:$L,$B9,MEL!$U:$U,"FUT") -> 0 | I9: =G9+H9 -> 2800 | J9: =SUMIFS(MEL!X:X,MEL!X:X,"<>",MEL!$L:$L,$B9,MEL!$U:$U,"PERM") -> 3220 | K9: =SUMIFS(MEL!X:X,MEL!X:X,"<>",MEL!$L:$L,$B9,MEL!$U:$U,"TEMP")+SUMIFS(MEL!X:X,MEL!X:X,"<>",MEL!$L:$L,$B9,MEL!$U:$U,"FUT") -> 0 | L9: =J9+K9 -> 3220 | M9: =SUMIFS(MEL!Y:Y,MEL!Y:Y,"<>",MEL!$L:$L,$B9,MEL!$U:$U,"PERM") -> 7500 | N9: =SUMIFS(MEL!Y:Y,MEL!Y:Y,"<>",MEL!$L:$L,$B9,MEL!$U:$U,"TEMP")+SUMIFS(MEL!Y:Y,MEL!Y:Y,"<>",MEL!$L:$L,$B9,MEL!$U:$U,"FUT") -> 0 | O9: =M9+N9 -> 7500
B10: Flare tower | D10: =SUMIFS(MEL!R:R,MEL!R:R,"<>",MEL!$L:$L,$B10,MEL!$U:$U,"PERM") -> 1.324844 | E10: =SUMIFS(MEL!R:R,MEL!R:R,"<>",MEL!$L:$L,$B10,MEL!$U:$U,"TEMP")+SUMIFS(MEL!R:R,MEL!R:R,"<>",MEL!$L:$L,$B10,MEL!$U:$U,"FUT") -> 0 | F10: =D10+E10 -> 1.324844 | G10: =SUMIFS(MEL!W:W,MEL!W:W,"<>",MEL!$L:$L,$B10,MEL!$U:$U,"PERM") -> 3265 | H10: =SUMIFS(MEL!W:W,MEL!W:W,"<>",MEL!$L:$L,$B10,MEL!$U:$U,"TEMP")+SUMIFS(MEL!W:W,MEL!W:W,"<>",MEL!$L:$L,$B10,MEL!$U:$U,"FUT") -> 0 | I10: =G10+H10 -> 3265 | J10: =SUMIFS(MEL!X:X,MEL!X:X,"<>",MEL!$L:$L,$B10,MEL!$U:$U,"PERM") -> 3754.75 | K10: =SUMIFS(MEL!X:X,MEL!X:X,"<>",MEL!$L:$L,$B10,MEL!$U:$U,"TEMP")+SUMIFS(MEL!X:X,MEL!X:X,"<>",MEL!$L:$L,$B10,MEL!$U:$U,"FUT") -> 0 | L10: =J10+K10 -> 3754.75 | M10: =SUMIFS(MEL!Y:Y,MEL!Y:Y,"<>",MEL!$L:$L,$B10,MEL!$U:$U,"PERM") -> 0 | N10: =SUMIFS(MEL!Y:Y,MEL!Y:Y,"<>",MEL!$L:$L,$B10,MEL!$U:$U,"TEMP")+SUMIFS(MEL!Y:Y,MEL!Y:Y,"<>",MEL!$L:$L,$B10,MEL!$U:$U,"FUT") -> 0 | O10: =M10+N10 -> 0
B11: Crane | D11: =SUMIFS(MEL!R:R,MEL!R:R,"<>",MEL!$L:$L,$B11,MEL!$U:$U,"PERM") -> 220.48 | E11: =SUMIFS(MEL!R:R,MEL!R:R,"<>",MEL!$L:$L,$B11,MEL!$U:$U,"TEMP")+SUMIFS(MEL!R:R,MEL!R:R,"<>",MEL!$L:$L,$B11,MEL!$U:$U,"FUT") -> 0 | F11: =D11+E11 -> 220.48 | G11: =SUMIFS(MEL!W:W,MEL!W:W,"<>",MEL!$L:$L,$B11,MEL!$U:$U,"PERM") -> 169300 | H11: =SUMIFS(MEL!W:W,MEL!W:W,"<>",MEL!$L:$L,$B11,MEL!$U:$U,"TEMP")+SUMIFS(MEL!W:W,MEL!W:W,"<>",MEL!$L:$L,$B11,MEL!$U:$U,"FUT") -> 0 | I11: =G11+H11 -> 169300 | J11: =SUMIFS(MEL!X:X,MEL!X:X,"<>",MEL!$L:$L,$B11,MEL!$U:$U,"PERM") -> 194695 | K11: =SUMIFS(MEL!X:X,MEL!X:X,"<>",MEL!$L:$L,$B11,MEL!$U:$U,"TEMP")+SUMIFS(MEL!X:X,MEL!X:X,"<>",MEL!$L:$L,$B11,MEL!$U:$U,"FUT") -> 0 | L11: =J11+K11 -> 194695 | M11: =SUMIFS(MEL!Y:Y,MEL!Y:Y,"<>",MEL!$L:$L,$B11,MEL!$U:$U,"PERM") -> 0 | N11: =SUMIFS(MEL!Y:Y,MEL!Y:Y,"<>",MEL!$L:$L,$B11,MEL!$U:$U,"TEMP")+SUMIFS(MEL!Y:Y,MEL!Y:Y,"<>",MEL!$L:$L,$B11,MEL!$U:$U,"FUT") -> 0 | O11: =M11+N11 -> 0
D12: =SUMIFS(MEL!R:R,MEL!R:R,"<>",MEL!$L:$L,$B12,MEL!$U:$U,"PERM") -> 0 | E12: =SUMIFS(MEL!R:R,MEL!R:R,"<>",MEL!$L:$L,$B12,MEL!$U:$U,"TEMP")+SUMIFS(MEL!R:R,MEL!R:R,"<>",MEL!$L:$L,$B12,MEL!$U:$U,"FUT") -> 0 | F12: =D12+E12 -> 0 | G12: =SUMIFS(MEL!W:W,MEL!W:W,"<>",MEL!$L:$L,$B12,MEL!$U:$U,"PERM") -> 0 | H12: =SUMIFS(MEL!W:W,MEL!W:W,"<>",MEL!$L:$L,$B12,MEL!$U:$U,"TEMP")+SUMIFS(MEL!W:W,MEL!W:W,"<>",MEL!$L:$L,$B12,MEL!$U:$U,"FUT") -> 0 | I12: =G12+H12 -> 0 | J12: =SUMIFS(MEL!X:X,MEL!X:X,"<>",MEL!$L:$L,$B12,MEL!$U:$U,"PERM") -> 0 | K12: =SUMIFS(MEL!X:X,MEL!X:X,"<>",MEL!$L:$L,$B12,MEL!$U:$U,"TEMP")+SUMIFS(MEL!X:X,MEL!X:X,"<>",MEL!$L:$L,$B12,MEL!$U:$U,"FUT") -> 0 | L12: =J12+K12 -> 0 | M12: =SUMIFS(MEL!Y:Y,MEL!Y:Y,"<>",MEL!$L:$L,$B12,MEL!$U:$U,"PERM") -> 0 | N12: =SUMIFS(MEL!Y:Y,MEL!Y:Y,"<>",MEL!$L:$L,$B12,MEL!$U:$U,"TEMP")+SUMIFS(MEL!Y:Y,MEL!Y:Y,"<>",MEL!$L:$L,$B12,MEL!$U:$U,"FUT") -> 0 | O12: =M12+N12 -> 0
B13: Total | D13: =SUM(D4:D12) -> 1107.7519 | E13: =SUM(E4:E12) -> 132.22051 | F13: =SUM(F4:F12) -> 1239.9724 | G13: =SUM(G4:G12) -> 1313778.7 | H13: =SUM(H4:H12) -> 128620 | I13: =SUM(I4:I12) -> 1442398.7 | J13: =SUM(J4:J12) -> 1509317.1 | K13: =SUM(K4:K12) -> 147913 | ... O13: =SUM(O4:O12) -> 278133.61
B17: Summary per discipline
B18: Discipline | C18: Description | D18: Footprint PERM (m2) | E18: Footprint FUT/ TEMP (m2) | F18: Footprint total (m2) | G18: Net Dry Weight PERM (kg) | H18: Net Dry Weight FUT/ TEMP (kg) | I18: Net Dry Weight total (kg) | J18: Gross Dry Weight PERM (kg) | K18: Gross Dry Weight FUT/ TEMP (kg) | L18: Gross Dry Weight total (kg) | M18: Content Weight PERM (kg) | N18: Content Weight FUT/ TEMP (kg) | O18: Content Weight total (kg)
B19: A | C19: Project management and administration | D19: =SUMIFS(MEL!R:R,MEL!R:R,"<>",MEL!C:C,B19,MEL!U:U,"PERM") -> 0.32 | E19: =SUMIFS(MEL!R:R,MEL!R:R,"<>",MEL!C:C,B19,MEL!U:U,"FUT")+SUMIFS(MEL!R:R,MEL!R:R,"<>",MEL!C:C,B19,MEL!U:U,"TEMP") -> 0 | F19: =E19+D19 -> 0.32 | G19: =SUMIFS(MEL!W:W,MEL!W:W,"<>",MEL!C:C,B19,MEL!U:U,"PERM") -> 200 | H19: =SUMIFS(MEL!W:W,MEL!W:W,"<>",MEL!C:C,B19,MEL!U:U,"FUT")+SUMIFS(MEL!W:W,MEL!W:W,"<>",MEL!C:C,B19,MEL!U:U,"TEMP") -> 0 | I19: =G19+H19 -> 200 | J19: =SUMIFS(MEL!X:X,MEL!X:X,"<>",MEL!C:C,B19,MEL!U:U,"PERM") -> 230 | K19: =SUMIFS(MEL!X:X,MEL!X:X,"<>",MEL!C:C,B19,MEL!U:U,"FUT")+SUMIFS(MEL!X:X,MEL!X:X,"<>",MEL!C:C,B19,MEL!U:U,"TEMP") -> 0 | L19: =J19+K19 -> 230 | M19: =SUMIFS(MEL!Y:Y,MEL!Y:Y,"<>",MEL!C:C,B19,MEL!U:U,"PERM") -> 0 | N19: =SUMIFS(MEL!Y:Y,MEL!Y:Y,"<>",MEL!C:C,B19,MEL!U:U,"FUT")+SUMIFS(MEL!Y:Y,MEL!Y:Y,"<>",MEL!C:C,B19,MEL!U:U,"TEMP") -> 0 | O19: =M19+N19 -> 0
B20: B | C20: Procurement | D20: =SUMIFS(MEL!R:R,MEL!R:R,"<>",MEL!C:C,B20,MEL!U:U,"PERM") -> 0 | E20: =SUMIFS(MEL!R:R,MEL!R:R,"<>",MEL!C:C,B20,MEL!U:U,"FUT")+SUMIFS(MEL!R:R,MEL!R:R,"<>",MEL!C:C,B20,MEL!U:U,"TEMP") -> 0 | F20: =E20+D20 -> 0 | G20: =SUMIFS(MEL!W:W,MEL!W:W,"<>",MEL!C:C,B20,MEL!U:U,"PERM") -> 0 | H20: =SUMIFS(MEL!W:W,MEL!W:W,"<>",MEL!C:C,B20,MEL!U:U,"FUT")+SUMIFS(MEL!W:W,MEL!W:W,"<>",MEL!C:C,B20,MEL!U:U,"TEMP") -> 0 | I20: =G20+H20 -> 0 | J20: =SUMIFS(MEL!X:X,MEL!X:X,"<>",MEL!C:C,B20,MEL!U:U,"PERM") -> 0 | K20: =SUMIFS(MEL!X:X,MEL!X:X,"<>",MEL!C:C,B20,MEL!U:U,"FUT")+SUMIFS(MEL!X:X,MEL!X:X,"<>",MEL!C:C,B20,MEL!U:U,"TEMP") -> 0 | L20: =J20+K20 -> 0 | M20: =SUMIFS(MEL!Y:Y,MEL!Y:Y,"<>",MEL!C:C,B20,MEL!U:U,"PERM") -> 0 | N20: =SUMIFS(MEL!Y:Y,MEL!Y:Y,"<>",MEL!C:C,B20,MEL!U:U,"FUT")+SUMIFS(MEL!Y:Y,MEL!Y:Y,"<>",MEL!C:C,B20,MEL!U:U,"TEMP") -> 0 | O20: =M20+N20 -> 0
B21: C | C21: Architect and building | D21: =SUMIFS(MEL!R:R,MEL!R:R,"<>",MEL!C:C,B21,MEL!U:U,"PERM") -> 0 | E21: =SUMIFS(MEL!R:R,MEL!R:R,"<>",MEL!C:C,B21,MEL!U:U,"FUT")+SUMIFS(MEL!R:R,MEL!R:R,"<>",MEL!C:C,B21,MEL!U:U,"TEMP") -> 0 | F21: =E21+D21 -> 0 | G21: =SUMIFS(MEL!W:W,MEL!W:W,"<>",MEL!C:C,B21,MEL!U:U,"PERM") -> 0 | H21: =SUMIFS(MEL!W:W,MEL!W:W,"<>",MEL!C:C,B21,MEL!U:U,"FUT")+SUMIFS(MEL!W:W,MEL!W:W,"<>",MEL!C:C,B21,MEL!U:U,"TEMP") -> 0 | I21: =G21+H21 -> 0 | J21: =SUMIFS(MEL!X:X,MEL!X:X,"<>",MEL!C:C,B21,MEL!U:U,"PERM") -> 0 | K21: =SUMIFS(MEL!X:X,MEL!X:X,"<>",MEL!C:C,B21,MEL!U:U,"FUT")+SUMIFS(MEL!X:X,MEL!X:X,"<>",MEL!C:C,B21,MEL!U:U,"TEMP") -> 0 | L21: =J21+K21 -> 0 | M21: =SUMIFS(MEL!Y:Y,MEL!Y:Y,"<>",MEL!C:C,B21,MEL!U:U,"PERM") -> 0 | N21: =SUMIFS(MEL!Y:Y,MEL!Y:Y,"<>",MEL!C:C,B21,MEL!U:U,"FUT")+SUMIFS(MEL!Y:Y,MEL!Y:Y,"<>",MEL!C:C,B21,MEL!U:U,"TEMP") -> 0 | O21: =M21+N21 -> 0
B22: D | C22: Drilling | D22: =SUMIFS(MEL!R:R,MEL!R:R,"<>",MEL!C:C,B22,MEL!U:U,"PERM") -> 0 | E22: =SUMIFS(MEL!R:R,MEL!R:R,"<>",MEL!C:C,B22,MEL!U:U,"FUT")+SUMIFS(MEL!R:R,MEL!R:R,"<>",MEL!C:C,B22,MEL!U:U,"TEMP") -> 0 | F22: =E22+D22 -> 0 | G22: =SUMIFS(MEL!W:W,MEL!W:W,"<>",MEL!C:C,B22,MEL!U:U,"PERM") -> 0 | H22: =SUMIFS(MEL!W:W,MEL!W:W,"<>",MEL!C:C,B22,MEL!U:U,"FUT")+SUMIFS(MEL!W:W,MEL!W:W,"<>",MEL!C:C,B22,MEL!U:U,"TEMP") -> 0 | I22: =G22+H22 -> 0 | J22: =SUMIFS(MEL!X:X,MEL!X:X,"<>",MEL!C:C,B22,MEL!U:U,"PERM") -> 0 | K22: =SUMIFS(MEL!X:X,MEL!X:X,"<>",MEL!C:C,B22,MEL!U:U,"FUT")+SUMIFS(MEL!X:X,MEL!X:X,"<>",MEL!C:C,B22,MEL!U:U,"TEMP") -> 0 | L22: =J22+K22 -> 0 | M22: =SUMIFS(MEL!Y:Y,MEL!Y:Y,"<>",MEL!C:C,B22,MEL!U:U,"PERM") -> 0 | N22: =SUMIFS(MEL!Y:Y,MEL!Y:Y,"<>",MEL!C:C,B22,MEL!U:U,"FUT")+SUMIFS(MEL!Y:Y,MEL!Y:Y,"<>",MEL!C:C,B22,MEL!U:U,"TEMP") -> 0 | O22: =M22+N22 -> 0
B23: E | C23: Electrical | D23: =SUMIFS(MEL!R:R,MEL!R:R,"<>",MEL!C:C,B23,MEL!U:U,"PERM") -> 294.6976 | E23: =SUMIFS(MEL!R:R,MEL!R:R,"<>",MEL!C:C,B23,MEL!U:U,"FUT")+SUMIFS(MEL!R:R,MEL!R:R,"<>",MEL!C:C,B23,MEL!U:U,"TEMP") -> 12.032 | F23: =E23+D23 -> 306.7296 | G23: =SUMIFS(MEL!W:W,MEL!W:W,"<>",MEL!C:C,B23,MEL!U:U,"PERM") -> 338781.74 | H23: =SUMIFS(MEL!W:W,MEL!W:W,"<>",MEL!C:C,B23,MEL!U:U,"FUT")+SUMIFS(MEL!W:W,MEL!W:W,"<>",MEL!C:C,B23,MEL!U:U,"TEMP") -> 9600 | I23: =G23+H23 -> 348381.74 | J23: =SUMIFS(MEL!X:X,MEL!X:X,"<>",MEL!C:C,B23,MEL!U:U,"PERM") -> 389399 | K23: =SUMIFS(MEL!X:X,MEL!X:X,"<>",MEL!C:C,B23,MEL!U:U,"FUT")+SUMIFS(MEL!X:X,MEL!X:X,"<>",MEL!C:C,B23,MEL!U:U,"TEMP") -> 11040 | L23: =J23+K23 -> 400439 | M23: =SUMIFS(MEL!Y:Y,MEL!Y:Y,"<>",MEL!C:C,B23,MEL!U:U,"PERM") -> 43943.61 | N23: =SUMIFS(MEL!Y:Y,MEL!Y:Y,"<>",MEL!C:C,B23,MEL!U:U,"FUT")+SUMIFS(MEL!Y:Y,MEL!Y:Y,"<>",MEL!C:C,B23,MEL!U:U,"TEMP") -> 0 | O23: =M23+N23 -> 43943.61
B24: F | C24: Reservoir | D24: =SUMIFS(MEL!R:R,MEL!R:R,"<>",MEL!C:C,B24,MEL!U:U,"PERM") -> 0 | E24: =SUMIFS(MEL!R:R,MEL!R:R,"<>",MEL!C:C,B24,MEL!U:U,"FUT")+SUMIFS(MEL!R:R,MEL!R:R,"<>",MEL!C:C,B24,MEL!U:U,"TEMP") -> 0 | F24: =E24+D24 -> 0 | G24: =SUMIFS(MEL!W:W,MEL!W:W,"<>",MEL!C:C,B24,MEL!U:U,"PERM") -> 0 | H24: =SUMIFS(MEL!W:W,MEL!W:W,"<>",MEL!C:C,B24,MEL!U:U,"FUT")+SUMIFS(MEL!W:W,MEL!W:W,"<>",MEL!C:C,B24,MEL!U:U,"TEMP") -> 0 | I24: =G24+H24 -> 0 | J24: =SUMIFS(MEL!X:X,MEL!X:X,"<>",MEL!C:C,B24,MEL!U:U,"PERM") -> 0 | K24: =SUMIFS(MEL!X:X,MEL!X:X,"<>",MEL!C:C,B24,MEL!U:U,"FUT")+SUMIFS(MEL!X:X,MEL!X:X,"<>",MEL!C:C,B24,MEL!U:U,"TEMP") -> 0 | L24: =J24+K24 -> 0 | M24: =SUMIFS(MEL!Y:Y,MEL!Y:Y,"<>",MEL!C:C,B24,MEL!U:U,"PERM") -> 0 | N24: =SUMIFS(MEL!Y:Y,MEL!Y:Y,"<>",MEL!C:C,B24,MEL!U:U,"FUT")+SUMIFS(MEL!Y:Y,MEL!Y:Y,"<>",MEL!C:C,B24,MEL!U:U,"TEMP") -> 0 | O24: =M24+N24 -> 0
B25: G | C25: Geosciences | D25: =SUMIFS(MEL!R:R,MEL!R:R,"<>",MEL!C:C,B25,MEL!U:U,"PERM") -> 0 | E25: =SUMIFS(MEL!R:R,MEL!R:R,"<>",MEL!C:C,B25,MEL!U:U,"FUT")+SUMIFS(MEL!R:R,MEL!R:R,"<>",MEL!C:C,B25,MEL!U:U,"TEMP") -> 0 | F25: =E25+D25 -> 0 | G25: =SUMIFS(MEL!W:W,MEL!W:W,"<>",MEL!C:C,B25,MEL!U:U,"PERM") -> 0 | H25: =SUMIFS(MEL!W:W,MEL!W:W,"<>",MEL!C:C,B25,MEL!U:U,"FUT")+SUMIFS(MEL!W:W,MEL!W:W,"<>",MEL!C:C,B25,MEL!U:U,"TEMP") -> 0 | I25: =G25+H25 -> 0 | J25: =SUMIFS(MEL!X:X,MEL!X:X,"<>",MEL!C:C,B25,MEL!U:U,"PERM") -> 0 | K25: =SUMIFS(MEL!X:X,MEL!X:X,"<>",MEL!C:C,B25,MEL!U:U,"FUT")+SUMIFS(MEL!X:X,MEL!X:X,"<>",MEL!C:C,B25,MEL!U:U,"TEMP") -> 0 | L25: =J25+K25 -> 0 | M25: =SUMIFS(MEL!Y:Y,MEL!Y:Y,"<>",MEL!C:C,B25,MEL!U:U,"PERM") -> 0 | N25: =SUMIFS(MEL!Y:Y,MEL!Y:Y,"<>",MEL!C:C,B25,MEL!U:U,"FUT")+SUMIFS(MEL!Y:Y,MEL!Y:Y,"<>",MEL!C:C,B25,MEL!U:U,"TEMP") -> 0 | O25: =M25+N25 -> 0
B26: H | C26: HVAC | D26: =SUMIFS(MEL!R:R,MEL!R:R,"<>",MEL!C:C,B26,MEL!U:U,"PERM") -> 93.1278 | E26: =SUMIFS(MEL!R:R,MEL!R:R,"<>",MEL!C:C,B26,MEL!U:U,"FUT")+SUMIFS(MEL!R:R,MEL!R:R,"<>",MEL!C:C,B26,MEL!U:U,"TEMP") -> 0 | F26: =E26+D26 -> 93.1278 | G26: =SUMIFS(MEL!W:W,MEL!W:W,"<>",MEL!C:C,B26,MEL!U:U,"PERM") -> 47290 | H26: =SUMIFS(MEL!W:W,MEL!W:W,"<>",MEL!C:C,B26,MEL!U:U,"FUT")+SUMIFS(MEL!W:W,MEL!W:W,"<>",MEL!C:C,B26,MEL!U:U,"TEMP") -> 0 | I26: =G26+H26 -> 47290 | J26: =SUMIFS(MEL!X:X,MEL!X:X,"<>",MEL!C:C,B26,MEL!U:U,"PERM") -> 54377.5 | K26: =SUMIFS(MEL!X:X,MEL!X:X,"<>",MEL!C:C,B26,MEL!U:U,"FUT")+SUMIFS(MEL!X:X,MEL!X:X,"<>",MEL!C:C,B26,MEL!U:U,"TEMP") -> 0 | L26: =J26+K26 -> 54377.5 | M26: =SUMIFS(MEL!Y:Y,MEL!Y:Y,"<>",MEL!C:C,B26,MEL!U:U,"PERM") -> 0 | N26: =SUMIFS(MEL!Y:Y,MEL!Y:Y,"<>",MEL!C:C,B26,MEL!U:U,"FUT")+SUMIFS(MEL!Y:Y,MEL!Y:Y,"<>",MEL!C:C,B26,MEL!U:U,"TEMP") -> 0 | O26: =M26+N26 -> 0
B27: J | C27: Automation | D27: =SUMIFS(MEL!R:R,MEL!R:R,"<>",MEL!C:C,B27,MEL!U:U,"PERM") -> 84.13 | E27: =SUMIFS(MEL!R:R,MEL!R:R,"<>",MEL!C:C,B27,MEL!U:U,"FUT")+SUMIFS(MEL!R:R,MEL!R:R,"<>",MEL!C:C,B27,MEL!U:U,"TEMP") -> 4.48 | F27: =E27+D27 -> 88.61 | G27: =SUMIFS(MEL!W:W,MEL!W:W,"<>",MEL!C:C,B27,MEL!U:U,"PERM") -> 37660 | H27: =SUMIFS(MEL!W:W,MEL!W:W,"<>",MEL!C:C,B27,MEL!U:U,"FUT")+SUMIFS(MEL!W:W,MEL!W:W,"<>",MEL!C:C,B27,MEL!U:U,"TEMP") -> 2000 | I27: =G27+H27 -> 39660 | J27: =SUMIFS(MEL!X:X,MEL!X:X,"<>",MEL!C:C,B27,MEL!U:U,"PERM") -> 43309 | K27: =SUMIFS(MEL!X:X,MEL!X:X,"<>",MEL!C:C,B27,MEL!U:U,"FUT")+SUMIFS(MEL!X:X,MEL!X:X,"<>",MEL!C:C,B27,MEL!U:U,"TEMP") -> 2300 | L27: =J27+K27 -> 45609 | M27: =SUMIFS(MEL!Y:Y,MEL!Y:Y,"<>",MEL!C:C,B27,MEL!U:U,"PERM") -> 4000 | N27: =SUMIFS(MEL!Y:Y,MEL!Y:Y,"<>",MEL!C:C,B27,MEL!U:U,"FUT")+SUMIFS(MEL!Y:Y,MEL!Y:Y,"<>",MEL!C:C,B27,MEL!U:U,"TEMP") -> 0 | O27: =M27+N27 -> 4000
B28: K | C28: Not in use | D28: =SUMIFS(MEL!R:R,MEL!R:R,"<>",MEL!C:C,B28,MEL!U:U,"PERM") -> 0 | E28: =SUMIFS(MEL!R:R,MEL!R:R,"<>",MEL!C:C,B28,MEL!U:U,"FUT")+SUMIFS(MEL!R:R,MEL!R:R,"<>",MEL!C:C,B28,MEL!U:U,"TEMP") -> 0 | F28: =E28+D28 -> 0 | G28: =SUMIFS(MEL!W:W,MEL!W:W,"<>",MEL!C:C,B28,MEL!U:U,"PERM") -> 0 | H28: =SUMIFS(MEL!W:W,MEL!W:W,"<>",MEL!C:C,B28,MEL!U:U,"FUT")+SUMIFS(MEL!W:W,MEL!W:W,"<>",MEL!C:C,B28,MEL!U:U,"TEMP") -> 0 | I28: =G28+H28 -> 0 | J28: =SUMIFS(MEL!X:X,MEL!X:X,"<>",MEL!C:C,B28,MEL!U:U,"PERM") -> 0 | K28: =SUMIFS(MEL!X:X,MEL!X:X,"<>",MEL!C:C,B28,MEL!U:U,"FUT")+SUMIFS(MEL!X:X,MEL!X:X,"<>",MEL!C:C,B28,MEL!U:U,"TEMP") -> 0 | L28: =J28+K28 -> 0 | M28: =SUMIFS(MEL!Y:Y,MEL!Y:Y,"<>",MEL!C:C,B28,MEL!U:U,"PERM") -> 0 | N28: =SUMIFS(MEL!Y:Y,MEL!Y:Y,"<>",MEL!C:C,B28,MEL!U:U,"FUT")+SUMIFS(MEL!Y:Y,MEL!Y:Y,"<>",MEL!C:C,B28,MEL!U:U,"TEMP") -> 0 | O28: =M28+N28 -> 0
B29: L | C29: Piping and Layout | D29: =SUMIFS(MEL!R:R,MEL!R:R,"<>",MEL!C:C,B29,MEL!U:U,"PERM") -> 0 | E29: =SUMIFS(MEL!R:R,MEL!R:R,"<>",MEL!C:C,B29,MEL!U:U,"FUT")+SUMIFS(MEL!R:R,MEL!R:R,"<>",MEL!C:C,B29,MEL!U:U,"TEMP") -> 0 | F29: =E29+D29 -> 0 | G29: =SUMIFS(MEL!W:W,MEL!W:W,"<>",MEL!C:C,B29,MEL!U:U,"PERM") -> 0 | H29: =SUMIFS(MEL!W:W,MEL!W:W,"<>",MEL!C:C,B29,MEL!U:U,"FUT")+SUMIFS(MEL!W:W,MEL!W:W,"<>",MEL!C:C,B29,MEL!U:U,"TEMP") -> 0 | I29: =G29+H29 -> 0 | J29: =SUMIFS(MEL!X:X,MEL!X:X,"<>",MEL!C:C,B29,MEL!U:U,"PERM") -> 0 | K29: =SUMIFS(MEL!X:X,MEL!X:X,"<>",MEL!C:C,B29,MEL!U:U,"FUT")+SUMIFS(MEL!X:X,MEL!X:X,"<>",MEL!C:C,B29,MEL!U:U,"TEMP") -> 0 | L29: =J29+K29 -> 0 | M29: =SUMIFS(MEL!Y:Y,MEL!Y:Y,"<>",MEL!C:C,B29,MEL!U:U,"PERM") -> 0 | N29: =SUMIFS(MEL!Y:Y,MEL!Y:Y,"<>",MEL!C:C,B29,MEL!U:U,"FUT")+SUMIFS(MEL!Y:Y,MEL!Y:Y,"<>",MEL!C:C,B29,MEL!U:U,"TEMP") -> 0 | O29: =M29+N29 -> 0
B30: M | C30: Material Technology | D30: =SUMIFS(MEL!R:R,MEL!R:R,"<>",MEL!C:C,B30,MEL!U:U,"PERM") -> 0 | E30: =SUMIFS(MEL!R:R,MEL!R:R,"<>",MEL!C:C,B30,MEL!U:U,"FUT")+SUMIFS(MEL!R:R,MEL!R:R,"<>",MEL!C:C,B30,MEL!U:U,"TEMP") -> 0 | F30: =E30+D30 -> 0 | G30: =SUMIFS(MEL!W:W,MEL!W:W,"<>",MEL!C:C,B30,MEL!U:U,"PERM") -> 0 | H30: =SUMIFS(MEL!W:W,MEL!W:W,"<>",MEL!C:C,B30,MEL!U:U,"FUT")+SUMIFS(MEL!W:W,MEL!W:W,"<>",MEL!C:C,B30,MEL!U:U,"TEMP") -> 0 | I30: =G30+H30 -> 0 | J30: =SUMIFS(MEL!X:X,MEL!X:X,"<>",MEL!C:C,B30,MEL!U:U,"PERM") -> 0 | K30: =SUMIFS(MEL!X:X,MEL!X:X,"<>",MEL!C:C,B30,MEL!U:U,"FUT")+SUMIFS(MEL!X:X,MEL!X:X,"<>",MEL!C:C,B30,MEL!U:U,"TEMP") -> 0 | L30: =J30+K30 -> 0 | M30: =SUMIFS(MEL!Y:Y,MEL!Y:Y,"<>",MEL!C:C,B30,MEL!U:U,"PERM") -> 0 | N30: =SUMIFS(MEL!Y:Y,MEL!Y:Y,"<>",MEL!C:C,B30,MEL!U:U,"FUT")+SUMIFS(MEL!Y:Y,MEL!Y:Y,"<>",MEL!C:C,B30,MEL!U:U,"TEMP") -> 0 | O30: =M30+N30 -> 0
... B42: Z | C42: Multidiscipline | D42: =SUMIFS(MEL!R:R,MEL!R:R,"<>",MEL!C:C,B42,MEL!U:U,"PERM") -> 0 | E42: =SUMIFS(MEL!R:R,MEL!R:R,"<>",MEL!C:C,B42,MEL!U:U,"FUT")+SUMIFS(MEL!R:R,MEL!R:R,"<>",MEL!C:C,B42,MEL!U:U,"TEMP") -> 0 | F42: =E42+D42 -> 0 | G42: =SUMIFS(MEL!W:W,MEL!W:W,"<>",MEL!C:C,B42,MEL!U:U,"PERM") -> 0 | H42: =SUMIFS(MEL!W:W,MEL!W:W,"<>",MEL!C:C,B42,MEL!U:U,"FUT")+SUMIFS(MEL!W:W,MEL!W:W,"<>",MEL!C:C,B42,MEL!U:U,"TEMP") -> 0 | I42: =G42+H42 -> 0 | J42: =SUMIFS(MEL!X:X,MEL!X:X,"<>",MEL!C:C,B42,MEL!U:U,"PERM") -> 0 | K42: =SUMIFS(MEL!X:X,MEL!X:X,"<>",MEL!C:C,B42,MEL!U:U,"FUT")+SUMIFS(MEL!X:X,MEL!X:X,"<>",MEL!C:C,B42,MEL!U:U,"TEMP") -> 0 | L42: =J42+K42 -> 0 | M42: =SUMIFS(MEL!Y:Y,MEL!Y:Y,"<>",MEL!C:C,B42,MEL!U:U,"PERM") -> 0 | N42: =SUMIFS(MEL!Y:Y,MEL!Y:Y,"<>",MEL!C:C,B42,MEL!U:U,"FUT")+SUMIFS(MEL!Y:Y,MEL!Y:Y,"<>",MEL!C:C,B42,MEL!U:U,"TEMP") -> 0 | O42: =M42+N42 -> 0
B43: Total | D43: =SUM(D19:D42) -> 1107.7519 | E43: =SUM(E19:E42) -> 132.22051 | F43: =SUM(F19:F42) -> 1239.9724 | G43: =SUM(G19:G42) -> 1313778.7 | H43: =SUM(H19:H42) -> 128620 | I43: =SUM(I19:I42) -> 1442398.7 | J43: =SUM(J19:J42) -> 1509317 | K43: =SUM(K19:K42) -> 147913 | ... O43: =SUM(O19:O42) -> 278133.61
B47: Summary per system group
B48: System no. | C48: Description | D48: Footprint PERM (m2) | E48: Footprint FUT/ TEMP (m2) | F48: Footprint total (m2) | G48: Net Dry Weight PERM (kg) | H48: Net Dry Weight FUT/ TEMP (kg) | I48: Net Dry Weight total (kg) | J48: Gross Dry Weight PERM (kg) | K48: Gross Dry Weight FUT/ TEMP (kg) | L48: Gross Dry Weight total (kg) | M48: Content Weight PERM (kg) | N48: Content Weight FUT/ TEMP (kg) | O48: Content Weight total (kg)
B49: 00 – 09 | C49: Project/facility specific systems | D49: =SUMIFS(MEL!R:R,MEL!R:R,"<>",MEL!$I:$I,">=0",MEL!$I:$I,"<=9",MEL!$U:$U,"PERM") -> 0 | E49: =SUMIFS(MEL!R:R,MEL!R:R,"<>",MEL!$I:$I,">=0",MEL!$I:$I,"<=9",MEL!$U:$U,"FUT")+SUMIFS(MEL!R:R,MEL!R:R,"<>",MEL!$I:$I,">=0",MEL!$I:$I,"<=9",MEL!$U:$U,"TEMP") -> 0 | F49: =D49+E49 -> 0 | G49: =SUMIFS(MEL!W:W,MEL!W:W,"<>",MEL!$I:$I,">=0",MEL!$I:$I,"<=9",MEL!$U:$U,"PERM") -> 0 | H49: =SUMIFS(MEL!W:W,MEL!W:W,"<>",MEL!$I:$I,">=0",MEL!$I:$I,"<=9",MEL!$U:$U,"FUT")+SUMIFS(MEL!W:W,MEL!W:W,"<>",MEL!$I:$I,">=0",MEL!$I:$I,"<=9",MEL!$U:$U,"TEMP") -> 0 | I49: =G49+H49 -> 0 | J49: =SUMIFS(MEL!X:X,MEL!X:X,"<>",MEL!$I:$I,">=0",MEL!$I:$I,"<=9",MEL!$U:$U,"PERM") -> 0 | K49: =SUMIFS(MEL!X:X,MEL!X:X,"<>",MEL!$I:$I,">=0",MEL!$I:$I,"<=9",MEL!$U:$U,"FUT")+SUMIFS(MEL!X:X,MEL!X:X,"<>",MEL!$I:$I,">=0",MEL!$I:$I,"<=9",MEL!$U:$U,"TEMP") -> 0 | L49: =J49+K49 -> 0 | M49: =SUMIFS(MEL!Y:Y,MEL!Y:Y,"<>",MEL!$I:$I,">=0",MEL!$I:$I,"<=9",MEL!$U:$U,"PERM") -> 0 | N49: =SUMIFS(MEL!Y:Y,MEL!Y:Y,"<>",MEL!$I:$I,">=0",MEL!$I:$I,"<=9",MEL!$U:$U,"FUT")+SUMIFS(MEL!Y:Y,MEL!Y:Y,"<>",MEL!$I:$I,">=0",MEL!$I:$I,"<=9",MEL!$U:$U,"TEMP") -> 0 | O49: =M49+N49 -> 0
B50: 10 – 19 | C50: Drilling, well and Subsea Production System (SPS) | D50: =SUMIFS(MEL!R:R,MEL!R:R,"<>",MEL!$I:$I,">=10",MEL!$I:$I,"<=19",MEL!$U:$U,"PERM") -> 48.3 | E50: =SUMIFS(MEL!R:R,MEL!R:R,"<>",MEL!$I:$I,">=10",MEL!$I:$I,"<=19",MEL!$U:$U,"FUT")+SUMIFS(MEL!R:R,MEL!R:R,"<>",MEL!$I:$I,">=10",MEL!$I:$I,"<=19",MEL!$U:$U,"TEMP") -> 4.72 | F50: =D50+E50 -> 53.02 | G50: =SUMIFS(MEL!W:W,MEL!W:W,"<>",MEL!$I:$I,">=10",MEL!$I:$I,"<=19",MEL!$U:$U,"PERM") -> 38300 | H50: =SUMIFS(MEL!W:W,MEL!W:W,"<>",MEL!$I:$I,">=10",MEL!$I:$I,"<=19",MEL!$U:$U,"FUT")+SUMIFS(MEL!W:W,MEL!W:W,"<>",MEL!$I:$I,">=10",MEL!$I:$I,"<=19",MEL!$U:$U,"TEMP") -> 13540 | I50: =G50+H50 -> 51840 | J50: =SUMIFS(MEL!X:X,MEL!X:X,"<>",MEL!$I:$I,">=10",MEL!$I:$I,"<=19",MEL!$U:$U,"PERM") -> 43845 | K50: =SUMIFS(MEL!X:X,MEL!X:X,"<>",MEL!$I:$I,">=10",MEL!$I:$I,"<=19",MEL!$U:$U,"FUT")+SUMIFS(MEL!X:X,MEL!X:X,"<>",MEL!$I:$I,">=10",MEL!$I:$I,"<=19",MEL!$U:$U,"TEMP") -> 15571 | L50: =J50+K50 -> 59416 | M50: =SUMIFS(MEL!Y:Y,MEL!Y:Y,"<>",MEL!$I:$I,">=10",MEL!$I:$I,"<=19",MEL!$U:$U,"PERM") -> 4000 | N50: =SUMIFS(MEL!Y:Y,MEL!Y:Y,"<>",MEL!$I:$I,">=10",MEL!$I:$I,"<=19",MEL!$U:$U,"FUT")+SUMIFS(MEL!Y:Y,MEL!Y:Y,"<>",MEL!$I:$I,">=10",MEL!$I:$I,"<=19",MEL!$U:$U,"TEMP") -> 0 | O50: =M50+N50 -> 4000
B51: 20 – 29 | C51: Main process systems | D51: =SUMIFS(MEL!R:R,MEL!R:R,"<>",MEL!$I:$I,">=20",MEL!$I:$I,"<=29",MEL!$U:$U,"PERM") -> 393.83875 | E51: =SUMIFS(MEL!R:R,MEL!R:R,"<>",MEL!$I:$I,">=20",MEL!$I:$I,"<=29",MEL!$U:$U,"FUT")+SUMIFS(MEL!R:R,MEL!R:R,"<>",MEL!$I:$I,">=20",MEL!$I:$I,"<=29",MEL!$U:$U,"TEMP") -> 12.08 | F51: =D51+E51 -> 405.91875 | G51: =SUMIFS(MEL!W:W,MEL!W:W,"<>",MEL!$I:$I,">=20",MEL!$I:$I,"<=29",MEL!$U:$U,"PERM") -> 726944 | H51: =SUMIFS(MEL!W:W,MEL!W:W,"<>",MEL!$I:$I,">=20",MEL!$I:$I,"<=29",MEL!$U:$U,"FUT")+SUMIFS(MEL!W:W,MEL!W:W,"<>",MEL!$I:$I,">=20",MEL!$I:$I,"<=29",MEL!$U:$U,"TEMP") -> 21270 | I51: =G51+H51 -> 748214 | J51: =SUMIFS(MEL!X:X,MEL!X:X,"<>",MEL!$I:$I,">=20",MEL!$I:$I,"<=29",MEL!$U:$U,"PERM") -> 835985.6 | K51: =SUMIFS(MEL!X:X,MEL!X:X,"<>",MEL!$I:$I,">=20",MEL!$I:$I,"<=29",MEL!$U:$U,"FUT")+SUMIFS(MEL!X:X,MEL!X:X,"<>",MEL!$I:$I,">=20",MEL!$I:$I,"<=29",MEL!$U:$U,"TEMP") -> 24460.5 | L51: =J51+K51 -> 860446.1 | M51: =SUMIFS(MEL!Y:Y,MEL!Y:Y,"<>",MEL!$I:$I,">=20",MEL!$I:$I,"<=29",MEL!$U:$U,"PERM") -> 168590 | N51: =SUMIFS(MEL!Y:Y,MEL!Y:Y,"<>",MEL!$I:$I,">=20",MEL!$I:$I,"<=29",MEL!$U:$U,"FUT")+SUMIFS(MEL!Y:Y,MEL!Y:Y,"<>",MEL!$I:$I,">=20",MEL!$I:$I,"<=29",MEL!$U:$U,"TEMP") -> 0 | O51: =M51+N51 -> 168590
B52: 30 – 39 | C52: Export and by-product handling systems | D52: =SUMIFS(MEL!R:R,MEL!R:R,"<>",MEL!$I:$I,">=30",MEL!$I:$I,"<=39",MEL!$U:$U,"PERM") -> 0 | E52: =SUMIFS(MEL!R:R,MEL!R:R,"<>",MEL!$I:$I,">=30",MEL!$I:$I,"<=39",MEL!$U:$U,"FUT")+SUMIFS(MEL!R:R,MEL!R:R,"<>",MEL!$I:$I,">=30",MEL!$I:$I,"<=39",MEL!$U:$U,"TEMP") -> 0 | F52: =D52+E52 -> 0 | G52: =SUMIFS(MEL!W:W,MEL!W:W,"<>",MEL!$I:$I,">=30",MEL!$I:$I,"<=39",MEL!$U:$U,"PERM") -> 0 | H52: =SUMIFS(MEL!W:W,MEL!W:W,"<>",MEL!$I:$I,">=30",MEL!$I:$I,"<=39",MEL!$U:$U,"FUT")+SUMIFS(MEL!W:W,MEL!W:W,"<>",MEL!$I:$I,">=30",MEL!$I:$I,"<=39",MEL!$U:$U,"TEMP") -> 0 | I52: =G52+H52 -> 0 | J52: =SUMIFS(MEL!X:X,MEL!X:X,"<>",MEL!$I:$I,">=30",MEL!$I:$I,"<=39",MEL!$U:$U,"PERM") -> 0 | K52: =SUMIFS(MEL!X:X,MEL!X:X,"<>",MEL!$I:$I,">=30",MEL!$I:$I,"<=39",MEL!$U:$U,"FUT")+SUMIFS(MEL!X:X,MEL!X:X,"<>",MEL!$I:$I,">=30",MEL!$I:$I,"<=39",MEL!$U:$U,"TEMP") -> 0 | L52: =J52+K52 -> 0 | M52: =SUMIFS(MEL!Y:Y,MEL!Y:Y,"<>",MEL!$I:$I,">=30",MEL!$I:$I,"<=39",MEL!$U:$U,"PERM") -> 0 | N52: =SUMIFS(MEL!Y:Y,MEL!Y:Y,"<>",MEL!$I:$I,">=30",MEL!$I:$I,"<=39",MEL!$U:$U,"FUT")+SUMIFS(MEL!Y:Y,MEL!Y:Y,"<>",MEL!$I:$I,">=30",MEL!$I:$I,"<=39",MEL!$U:$U,"TEMP") -> 0 | O52: =M52+N52 -> 0
B53: 40 – 69 | C53: Process support and utility systems | D53: =SUMIFS(MEL!R:R,MEL!R:R,"<>",MEL!$I:$I,">=40",MEL!$I:$I,"<=69",MEL!$U:$U,"PERM") -> 119.47774 | E53: =SUMIFS(MEL!R:R,MEL!R:R,"<>",MEL!$I:$I,">=40",MEL!$I:$I,"<=69",MEL!$U:$U,"FUT")+SUMIFS(MEL!R:R,MEL!R:R,"<>",MEL!$I:$I,">=40",MEL!$I:$I,"<=69",MEL!$U:$U,"TEMP") -> 80.762944 | F53: =D53+E53 -> 200.24069 | G53: =SUMIFS(MEL!W:W,MEL!W:W,"<>",MEL!$I:$I,">=40",MEL!$I:$I,"<=69",MEL!$U:$U,"PERM") -> 116203 | H53: =SUMIFS(MEL!W:W,MEL!W:W,"<>",MEL!$I:$I,">=40",MEL!$I:$I,"<=69",MEL!$U:$U,"FUT")+SUMIFS(MEL!W:W,MEL!W:W,"<>",MEL!$I:$I,">=40",MEL!$I:$I,"<=69",MEL!$U:$U,"TEMP") -> 71940 | I53: =G53+H53 -> 188143 | J53: =SUMIFS(MEL!X:X,MEL!X:X,"<>",MEL!$I:$I,">=40",MEL!$I:$I,"<=69",MEL!$U:$U,"PERM") -> 132310.95 | K53: =SUMIFS(MEL!X:X,MEL!X:X,"<>",MEL!$I:$I,">=40",MEL!$I:$I,"<=69",MEL!$U:$U,"FUT")+SUMIFS(MEL!X:X,MEL!X:X,"<>",MEL!$I:$I,">=40",MEL!$I:$I,"<=69",MEL!$U:$U,"TEMP") -> 82731 | L53: =J53+K53 -> 215041.95 | M53: =SUMIFS(MEL!Y:Y,MEL!Y:Y,"<>",MEL!$I:$I,">=40",MEL!$I:$I,"<=69",MEL!$U:$U,"PERM") -> 85600 | N53: =SUMIFS(MEL!Y:Y,MEL!Y:Y,"<>",MEL!$I:$I,">=40",MEL!$I:$I,"<=69",MEL!$U:$U,"FUT")+SUMIFS(MEL!Y:Y,MEL!Y:Y,"<>",MEL!$I:$I,">=40",MEL!$I:$I,"<=69",MEL!$U:$U,"TEMP") -> 0 | O53: =M53+N53 -> 85600
B54: 70 – 79 | C54: Safety systems | D54: =SUMIFS(MEL!R:R,MEL!R:R,"<>",MEL!$I:$I,">=70",MEL!$I:$I,"<=79",MEL!$U:$U,"PERM") -> 319.1816 | E54: =SUMIFS(MEL!R:R,MEL!R:R,"<>",MEL!$I:$I,">=70",MEL!$I:$I,"<=79",MEL!$U:$U,"FUT")+SUMIFS(MEL!R:R,MEL!R:R,"<>",MEL!$I:$I,">=70",MEL!$I:$I,"<=79",MEL!$U:$U,"TEMP") -> 30.177564 | F54: =D54+E54 -> 349.35916 | G54: =SUMIFS(MEL!W:W,MEL!W:W,"<>",MEL!$I:$I,">=70",MEL!$I:$I,"<=79",MEL!$U:$U,"PERM") -> 219430 | H54: =SUMIFS(MEL!W:W,MEL!W:W,"<>",MEL!$I:$I,">=70",MEL!$I:$I,"<=79",MEL!$U:$U,"FUT")+SUMIFS(MEL!W:W,MEL!W:W,"<>",MEL!$I:$I,">=70",MEL!$I:$I,"<=79",MEL!$U:$U,"TEMP") -> 19870 | I54: =G54+H54 -> 239300 | J54: =SUMIFS(MEL!X:X,MEL!X:X,"<>",MEL!$I:$I,">=70",MEL!$I:$I,"<=79",MEL!$U:$U,"PERM") -> 252338.5 | K54: =SUMIFS(MEL!X:X,MEL!X:X,"<>",MEL!$I:$I,">=70",MEL!$I:$I,"<=79",MEL!$U:$U,"FUT")+SUMIFS(MEL!X:X,MEL!X:X,"<>",MEL!$I:$I,">=70",MEL!$I:$I,"<=79",MEL!$U:$U,"TEMP") -> 22850.5 | L54: =J54+K54 -> 275189 | M54: =SUMIFS(MEL!Y:Y,MEL!Y:Y,"<>",MEL!$I:$I,">=70",MEL!$I:$I,"<=79",MEL!$U:$U,"PERM") -> 0 | N54: =SUMIFS(MEL!Y:Y,MEL!Y:Y,"<>",MEL!$I:$I,">=70",MEL!$I:$I,"<=79",MEL!$U:$U,"FUT")+SUMIFS(MEL!Y:Y,MEL!Y:Y,"<>",MEL!$I:$I,">=70",MEL!$I:$I,"<=79",MEL!$U:$U,"TEMP") -> 0 | O54: =M54+N54 -> 0
